[2023-08-02 22:30:45,590] {taskinstance.py:1179} INFO - Dependencies all met for <TaskInstance: vic_investigacion_ETL.profesores_validados manual__2023-08-02T22:30:41.645101+00:00 [queued]>
[2023-08-02 22:30:45,608] {taskinstance.py:1179} INFO - Dependencies all met for <TaskInstance: vic_investigacion_ETL.profesores_validados manual__2023-08-02T22:30:41.645101+00:00 [queued]>
[2023-08-02 22:30:45,611] {taskinstance.py:1376} INFO - 
--------------------------------------------------------------------------------
[2023-08-02 22:30:45,612] {taskinstance.py:1377} INFO - Starting attempt 1 of 1
[2023-08-02 22:30:45,615] {taskinstance.py:1378} INFO - 
--------------------------------------------------------------------------------
[2023-08-02 22:30:45,643] {taskinstance.py:1397} INFO - Executing <Task(PrepareProfesoresValidados): profesores_validados> on 2023-08-02 22:30:41.645101+00:00
[2023-08-02 22:30:45,689] {standard_task_runner.py:52} INFO - Started process 600 to run task
[2023-08-02 22:30:45,696] {standard_task_runner.py:79} INFO - Running: ['***', 'tasks', 'run', 'vic_investigacion_ETL', 'profesores_validados', 'manual__2023-08-02T22:30:41.645101+00:00', '--job-id', '204', '--raw', '--subdir', 'DAGS_FOLDER/vic_investigacion_dag.py', '--cfg-path', '/tmp/tmp53qpuva7', '--error-file', '/tmp/tmpp33nqkws']
[2023-08-02 22:30:45,703] {standard_task_runner.py:80} INFO - Job 204: Subtask profesores_validados
[2023-08-02 22:30:45,902] {task_command.py:371} INFO - Running <TaskInstance: vic_investigacion_ETL.profesores_validados manual__2023-08-02T22:30:41.645101+00:00 [running]> on host 6c8a51d4a614
[2023-08-02 22:30:46,022] {taskinstance.py:1591} INFO - Exporting the following env vars:
AIRFLOW_CTX_DAG_OWNER=***
AIRFLOW_CTX_DAG_ID=vic_investigacion_ETL
AIRFLOW_CTX_TASK_ID=profesores_validados
AIRFLOW_CTX_EXECUTION_DATE=2023-08-02T22:30:41.645101+00:00
AIRFLOW_CTX_TRY_NUMBER=1
AIRFLOW_CTX_DAG_RUN_ID=manual__2023-08-02T22:30:41.645101+00:00
[2023-08-02 22:30:46,032] {logging_mixin.py:115} INFO - Preparing Profesores validados
[2023-08-02 22:30:47,403] {taskinstance.py:1909} ERROR - Task failed with exception
Traceback (most recent call last):
  File "/opt/airflow/dags/prepare_profesores_validado_operator.py", line 31, in execute
    self.cleanData()
  File "/opt/airflow/dags/prepare_profesores_validado_operator.py", line 35, in cleanData
    self.cleanProfesoresValidados()
  File "/opt/airflow/dags/prepare_profesores_validado_operator.py", line 53, in cleanProfesoresValidados
    profesores.to_csv(f"{self.dag_path}/data/to_upload/rewrite/profesores_validados.csv",index=False)
  File "/home/airflow/.local/lib/python3.7/site-packages/pandas/core/generic.py", line 3482, in to_csv
    storage_options=storage_options,
  File "/home/airflow/.local/lib/python3.7/site-packages/pandas/io/formats/format.py", line 1105, in to_csv
    csv_formatter.save()
  File "/home/airflow/.local/lib/python3.7/site-packages/pandas/io/formats/csvs.py", line 243, in save
    storage_options=self.storage_options,
  File "/home/airflow/.local/lib/python3.7/site-packages/pandas/io/common.py", line 707, in get_handle
    newline="",
FileNotFoundError: [Errno 2] No such file or directory: '/opt/airflow/data/to_upload/rewrite/profesores_validados.csv'
[2023-08-02 22:30:47,633] {taskinstance.py:1420} INFO - Marking task as FAILED. dag_id=vic_investigacion_ETL, task_id=profesores_validados, execution_date=20230802T223041, start_date=20230802T223045, end_date=20230802T223047
[2023-08-02 22:30:47,687] {standard_task_runner.py:97} ERROR - Failed to execute job 204 for task profesores_validados ([Errno 2] No such file or directory: '/opt/airflow/data/to_upload/rewrite/profesores_validados.csv'; 600)
[2023-08-02 22:30:47,801] {local_task_job.py:156} INFO - Task exited with return code 1
