[2023-04-24 17:12:55,794] {taskinstance.py:1179} INFO - Dependencies all met for <TaskInstance: vic_investigacion_ETL.upload_data_big_query manual__2023-04-24T17:12:46.783653+00:00 [queued]>
[2023-04-24 17:12:55,803] {taskinstance.py:1179} INFO - Dependencies all met for <TaskInstance: vic_investigacion_ETL.upload_data_big_query manual__2023-04-24T17:12:46.783653+00:00 [queued]>
[2023-04-24 17:12:55,804] {taskinstance.py:1376} INFO - 
--------------------------------------------------------------------------------
[2023-04-24 17:12:55,805] {taskinstance.py:1377} INFO - Starting attempt 1 of 1
[2023-04-24 17:12:55,805] {taskinstance.py:1378} INFO - 
--------------------------------------------------------------------------------
[2023-04-24 17:12:55,815] {taskinstance.py:1397} INFO - Executing <Task(ExportData): upload_data_big_query> on 2023-04-24 17:12:46.783653+00:00
[2023-04-24 17:12:55,820] {standard_task_runner.py:52} INFO - Started process 5472 to run task
[2023-04-24 17:12:55,825] {standard_task_runner.py:79} INFO - Running: ['***', 'tasks', 'run', 'vic_investigacion_ETL', 'upload_data_big_query', 'manual__2023-04-24T17:12:46.783653+00:00', '--job-id', '382', '--raw', '--subdir', 'DAGS_FOLDER/vic_investigacion_dag.py', '--cfg-path', '/tmp/tmppxi87x49', '--error-file', '/tmp/tmpisa7re0t']
[2023-04-24 17:12:55,827] {standard_task_runner.py:80} INFO - Job 382: Subtask upload_data_big_query
[2023-04-24 17:12:55,892] {task_command.py:371} INFO - Running <TaskInstance: vic_investigacion_ETL.upload_data_big_query manual__2023-04-24T17:12:46.783653+00:00 [running]> on host b136a0a45498
[2023-04-24 17:12:55,949] {taskinstance.py:1591} INFO - Exporting the following env vars:
AIRFLOW_CTX_DAG_OWNER=***
AIRFLOW_CTX_DAG_ID=vic_investigacion_ETL
AIRFLOW_CTX_TASK_ID=upload_data_big_query
AIRFLOW_CTX_EXECUTION_DATE=2023-04-24T17:12:46.783653+00:00
AIRFLOW_CTX_TRY_NUMBER=1
AIRFLOW_CTX_DAG_RUN_ID=manual__2023-04-24T17:12:46.783653+00:00
[2023-04-24 17:12:55,951] {logging_mixin.py:115} INFO - Exporting Data
[2023-04-24 17:12:56,112] {logging_mixin.py:115} INFO - Scopus_id          int64
orcid             object
document_count     int64
cited_by_count     int64
citation_count     int64
pick_date         object
dtype: object
[2023-04-24 17:13:02,734] {logging_mixin.py:115} INFO - LoadJob<project=viceinvestigacion, location=US, id=b47a5438-b222-486a-ba63-695479a1e521>
[2023-04-24 17:13:02,752] {logging_mixin.py:115} INFO - Scopus_id                                                                           int64
orcid                                                                              object
document_count                                                                      int64
cited_by_count                                                                      int64
citation_count                                                                      int64
pick_date                                                                          object
status                                                                             object
affiliation_current.affiliation.@affiliation_id                                     int64
affiliation_current.affiliation.ip_doc.@relationship                               object
affiliation_current.affiliation.ip_doc.afdispname                                  object
affiliation_current.affiliation.ip_doc.manual_curation.date_curation.@day           int64
affiliation_current.affiliation.ip_doc.manual_curation.date_curation.@month         int64
affiliation_current.affiliation.ip_doc.manual_curation.date_curation.@timestamp    object
affiliation_current.affiliation.ip_doc.manual_curation.date_curation.@year          int64
affiliation_current.affiliation.ip_doc.address.city                                object
affiliation_current.affiliation.ip_doc.address.postal_code                          int64
affiliation_current.affiliation.ip_doc.address.country                             object
dtype: object
[2023-04-24 17:13:03,186] {taskinstance.py:1909} ERROR - Task failed with exception
Traceback (most recent call last):
  File "/home/airflow/.local/lib/python3.7/site-packages/google/cloud/bigquery/client.py", line 2452, in load_table_from_file
    file_obj, job_resource, size, num_retries, timeout, project=project
  File "/home/airflow/.local/lib/python3.7/site-packages/google/cloud/bigquery/client.py", line 3022, in _do_multipart_upload
    self._http, data, metadata, _GENERIC_CONTENT_TYPE, timeout=timeout
  File "/home/airflow/.local/lib/python3.7/site-packages/google/resumable_media/requests/upload.py", line 154, in transmit
    retriable_request, self._get_status_code, self._retry_strategy
  File "/home/airflow/.local/lib/python3.7/site-packages/google/resumable_media/requests/_request_helpers.py", line 148, in wait_and_retry
    response = func()
  File "/home/airflow/.local/lib/python3.7/site-packages/google/resumable_media/requests/upload.py", line 149, in retriable_request
    self._process_response(result)
  File "/home/airflow/.local/lib/python3.7/site-packages/google/resumable_media/_upload.py", line 114, in _process_response
    _helpers.require_status_code(response, (http.client.OK,), self._get_status_code)
  File "/home/airflow/.local/lib/python3.7/site-packages/google/resumable_media/_helpers.py", line 110, in require_status_code
    *status_codes
google.resumable_media.common.InvalidResponse: ('Request failed with status code', 400, 'Expected one of', <HTTPStatus.OK: 200>)

During handling of the above exception, another exception occurred:

Traceback (most recent call last):
  File "/opt/airflow/dags/export_data_operator.py", line 28, in execute
    self.exporting_authors_core_data()
  File "/opt/airflow/dags/export_data_operator.py", line 73, in exporting_authors_core_data
    self.createTable(file_name,df)
  File "/opt/airflow/dags/export_data_operator.py", line 40, in createTable
    job= self.client.load_table_from_dataframe(df,full_table_id)
  File "/home/airflow/.local/lib/python3.7/site-packages/google/cloud/bigquery/client.py", line 2713, in load_table_from_dataframe
    timeout=timeout,
  File "/home/airflow/.local/lib/python3.7/site-packages/google/cloud/bigquery/client.py", line 2455, in load_table_from_file
    raise exceptions.from_http_response(exc.response)
google.api_core.exceptions.BadRequest: 400 POST https://bigquery.googleapis.com/upload/bigquery/v2/projects/viceinvestigacion/jobs?uploadType=multipart: Invalid field name "affiliation_current.affiliation.@affiliation_id". Fields must contain the allowed characters, and be at most 300 characters long. For allowed characters, please refer to https://cloud.google.com/bigquery/docs/schemas#column_names
[2023-04-24 17:13:03,229] {taskinstance.py:1420} INFO - Marking task as FAILED. dag_id=vic_investigacion_ETL, task_id=upload_data_big_query, execution_date=20230424T171246, start_date=20230424T171255, end_date=20230424T171303
[2023-04-24 17:13:03,251] {standard_task_runner.py:97} ERROR - Failed to execute job 382 for task upload_data_big_query (400 POST https://bigquery.googleapis.com/upload/bigquery/v2/projects/viceinvestigacion/jobs?uploadType=multipart: Invalid field name "affiliation_current.affiliation.@affiliation_id". Fields must contain the allowed characters, and be at most 300 characters long. For allowed characters, please refer to https://cloud.google.com/bigquery/docs/schemas#column_names; 5472)
[2023-04-24 17:13:03,395] {local_task_job.py:156} INFO - Task exited with return code 1
[2023-04-24 17:13:03,441] {local_task_job.py:273} INFO - 0 downstream tasks scheduled from follow-on schedule check
