[2023-08-01 23:32:14,983] {taskinstance.py:1179} INFO - Dependencies all met for <TaskInstance: vic_investigacion_ETL.proyectos manual__2023-08-01T23:32:12.145748+00:00 [queued]>
[2023-08-01 23:32:14,994] {taskinstance.py:1179} INFO - Dependencies all met for <TaskInstance: vic_investigacion_ETL.proyectos manual__2023-08-01T23:32:12.145748+00:00 [queued]>
[2023-08-01 23:32:14,995] {taskinstance.py:1376} INFO - 
--------------------------------------------------------------------------------
[2023-08-01 23:32:15,005] {taskinstance.py:1377} INFO - Starting attempt 1 of 1
[2023-08-01 23:32:15,009] {taskinstance.py:1378} INFO - 
--------------------------------------------------------------------------------
[2023-08-01 23:32:15,028] {taskinstance.py:1397} INFO - Executing <Task(PrepareProyectos): proyectos> on 2023-08-01 23:32:12.145748+00:00
[2023-08-01 23:32:15,047] {standard_task_runner.py:52} INFO - Started process 1860 to run task
[2023-08-01 23:32:15,054] {standard_task_runner.py:79} INFO - Running: ['***', 'tasks', 'run', 'vic_investigacion_ETL', 'proyectos', 'manual__2023-08-01T23:32:12.145748+00:00', '--job-id', '173', '--raw', '--subdir', 'DAGS_FOLDER/vic_investigacion_dag.py', '--cfg-path', '/tmp/tmp5a8_32r2', '--error-file', '/tmp/tmp1ayy2p5a']
[2023-08-01 23:32:15,060] {standard_task_runner.py:80} INFO - Job 173: Subtask proyectos
[2023-08-01 23:32:15,245] {task_command.py:371} INFO - Running <TaskInstance: vic_investigacion_ETL.proyectos manual__2023-08-01T23:32:12.145748+00:00 [running]> on host 6c8a51d4a614
[2023-08-01 23:32:15,562] {taskinstance.py:1591} INFO - Exporting the following env vars:
AIRFLOW_CTX_DAG_OWNER=***
AIRFLOW_CTX_DAG_ID=vic_investigacion_ETL
AIRFLOW_CTX_TASK_ID=proyectos
AIRFLOW_CTX_EXECUTION_DATE=2023-08-01T23:32:12.145748+00:00
AIRFLOW_CTX_TRY_NUMBER=1
AIRFLOW_CTX_DAG_RUN_ID=manual__2023-08-01T23:32:12.145748+00:00
[2023-08-01 23:32:15,573] {logging_mixin.py:115} INFO - Reading Journals
[2023-08-01 23:32:29,488] {taskinstance.py:1909} ERROR - Task failed with exception
Traceback (most recent call last):
  File "/home/airflow/.local/lib/python3.7/site-packages/pandas/core/tools/datetimes.py", line 509, in _to_datetime_with_format
    values, tz = conversion.datetime_to_datetime64(arg)
  File "pandas/_libs/tslibs/conversion.pyx", line 359, in pandas._libs.tslibs.conversion.datetime_to_datetime64
TypeError: Unrecognized value type: <class 'int'>

During handling of the above exception, another exception occurred:

Traceback (most recent call last):
  File "/opt/airflow/dags/prepare_proyectos_operator.py", line 22, in execute
    self.cleanData()
  File "/opt/airflow/dags/prepare_proyectos_operator.py", line 26, in cleanData
    self.cleanProyectos()
  File "/opt/airflow/dags/prepare_proyectos_operator.py", line 39, in cleanProyectos
    proyectos["FECHA_DE_NEGOCIACION"]=pd.to_datetime(proyectos["FECHA_DE_NEGOCIACION"],format='mixed')
  File "/home/airflow/.local/lib/python3.7/site-packages/pandas/core/tools/datetimes.py", line 883, in to_datetime
    cache_array = _maybe_cache(arg, format, cache, convert_listlike)
  File "/home/airflow/.local/lib/python3.7/site-packages/pandas/core/tools/datetimes.py", line 195, in _maybe_cache
    cache_dates = convert_listlike(unique_dates, format)
  File "/home/airflow/.local/lib/python3.7/site-packages/pandas/core/tools/datetimes.py", line 394, in _convert_listlike_datetimes
    arg, orig_arg, name, tz, format, exact, errors, infer_datetime_format
  File "/home/airflow/.local/lib/python3.7/site-packages/pandas/core/tools/datetimes.py", line 513, in _to_datetime_with_format
    raise err
  File "/home/airflow/.local/lib/python3.7/site-packages/pandas/core/tools/datetimes.py", line 501, in _to_datetime_with_format
    arg, name, tz, fmt, exact, errors, infer_datetime_format
  File "/home/airflow/.local/lib/python3.7/site-packages/pandas/core/tools/datetimes.py", line 436, in _array_strptime_with_fallback
    result, timezones = array_strptime(arg, fmt, exact=exact, errors=errors)
  File "pandas/_libs/tslibs/strptime.pyx", line 150, in pandas._libs.tslibs.strptime.array_strptime
ValueError: time data '2019' does not match format 'mixed' (match)
[2023-08-01 23:32:29,516] {taskinstance.py:1420} INFO - Marking task as FAILED. dag_id=vic_investigacion_ETL, task_id=proyectos, execution_date=20230801T233212, start_date=20230801T233214, end_date=20230801T233229
[2023-08-01 23:32:29,539] {standard_task_runner.py:97} ERROR - Failed to execute job 173 for task proyectos (time data '2019' does not match format 'mixed' (match); 1860)
[2023-08-01 23:32:29,669] {local_task_job.py:156} INFO - Task exited with return code 1
