[2023-08-02 22:30:45,547] {taskinstance.py:1179} INFO - Dependencies all met for <TaskInstance: vic_investigacion_ETL.semilleros manual__2023-08-02T22:30:41.645101+00:00 [queued]>
[2023-08-02 22:30:45,562] {taskinstance.py:1179} INFO - Dependencies all met for <TaskInstance: vic_investigacion_ETL.semilleros manual__2023-08-02T22:30:41.645101+00:00 [queued]>
[2023-08-02 22:30:45,563] {taskinstance.py:1376} INFO - 
--------------------------------------------------------------------------------
[2023-08-02 22:30:45,564] {taskinstance.py:1377} INFO - Starting attempt 1 of 1
[2023-08-02 22:30:45,565] {taskinstance.py:1378} INFO - 
--------------------------------------------------------------------------------
[2023-08-02 22:30:45,579] {taskinstance.py:1397} INFO - Executing <Task(PrepareSemilleros): semilleros> on 2023-08-02 22:30:41.645101+00:00
[2023-08-02 22:30:45,650] {standard_task_runner.py:52} INFO - Started process 599 to run task
[2023-08-02 22:30:45,662] {standard_task_runner.py:79} INFO - Running: ['***', 'tasks', 'run', 'vic_investigacion_ETL', 'semilleros', 'manual__2023-08-02T22:30:41.645101+00:00', '--job-id', '205', '--raw', '--subdir', 'DAGS_FOLDER/vic_investigacion_dag.py', '--cfg-path', '/tmp/tmp2c3qo9xd', '--error-file', '/tmp/tmpd42i2bsk']
[2023-08-02 22:30:45,672] {standard_task_runner.py:80} INFO - Job 205: Subtask semilleros
[2023-08-02 22:30:45,870] {task_command.py:371} INFO - Running <TaskInstance: vic_investigacion_ETL.semilleros manual__2023-08-02T22:30:41.645101+00:00 [running]> on host 6c8a51d4a614
[2023-08-02 22:30:46,001] {taskinstance.py:1591} INFO - Exporting the following env vars:
AIRFLOW_CTX_DAG_OWNER=***
AIRFLOW_CTX_DAG_ID=vic_investigacion_ETL
AIRFLOW_CTX_TASK_ID=semilleros
AIRFLOW_CTX_EXECUTION_DATE=2023-08-02T22:30:41.645101+00:00
AIRFLOW_CTX_TRY_NUMBER=1
AIRFLOW_CTX_DAG_RUN_ID=manual__2023-08-02T22:30:41.645101+00:00
[2023-08-02 22:30:46,004] {logging_mixin.py:115} INFO - Reading Semilleros
[2023-08-02 22:30:46,009] {taskinstance.py:1909} ERROR - Task failed with exception
Traceback (most recent call last):
  File "/opt/airflow/dags/prepare_semilleros_operator.py", line 22, in execute
    self.cleanData()
  File "/opt/airflow/dags/prepare_semilleros_operator.py", line 26, in cleanData
    self.cleanSemilleros()
  File "/opt/airflow/dags/prepare_semilleros_operator.py", line 30, in cleanSemilleros
    semilleros = pd.read_excel(f"{self.dag_path}/data/semilleros/rewrite/semilleros_template.xlsx")
  File "/home/airflow/.local/lib/python3.7/site-packages/pandas/util/_decorators.py", line 311, in wrapper
    return func(*args, **kwargs)
  File "/home/airflow/.local/lib/python3.7/site-packages/pandas/io/excel/_base.py", line 364, in read_excel
    io = ExcelFile(io, storage_options=storage_options, engine=engine)
  File "/home/airflow/.local/lib/python3.7/site-packages/pandas/io/excel/_base.py", line 1192, in __init__
    content_or_path=path_or_buffer, storage_options=storage_options
  File "/home/airflow/.local/lib/python3.7/site-packages/pandas/io/excel/_base.py", line 1071, in inspect_excel_format
    content_or_path, "rb", storage_options=storage_options, is_text=False
  File "/home/airflow/.local/lib/python3.7/site-packages/pandas/io/common.py", line 711, in get_handle
    handle = open(handle, ioargs.mode)
FileNotFoundError: [Errno 2] No such file or directory: '/opt/airflow/data/semilleros/rewrite/semilleros_template.xlsx'
[2023-08-02 22:30:46,043] {taskinstance.py:1420} INFO - Marking task as FAILED. dag_id=vic_investigacion_ETL, task_id=semilleros, execution_date=20230802T223041, start_date=20230802T223045, end_date=20230802T223046
[2023-08-02 22:30:46,063] {standard_task_runner.py:97} ERROR - Failed to execute job 205 for task semilleros ([Errno 2] No such file or directory: '/opt/airflow/data/semilleros/rewrite/semilleros_template.xlsx'; 599)
[2023-08-02 22:30:46,130] {local_task_job.py:156} INFO - Task exited with return code 1
