[2023-04-24 20:40:15,952] {taskinstance.py:1179} INFO - Dependencies all met for <TaskInstance: vic_investigacion_ETL.prepare_scopus_data manual__2023-04-24T20:39:52.033408+00:00 [queued]>
[2023-04-24 20:40:15,959] {taskinstance.py:1179} INFO - Dependencies all met for <TaskInstance: vic_investigacion_ETL.prepare_scopus_data manual__2023-04-24T20:39:52.033408+00:00 [queued]>
[2023-04-24 20:40:15,960] {taskinstance.py:1376} INFO - 
--------------------------------------------------------------------------------
[2023-04-24 20:40:15,961] {taskinstance.py:1377} INFO - Starting attempt 1 of 1
[2023-04-24 20:40:15,963] {taskinstance.py:1378} INFO - 
--------------------------------------------------------------------------------
[2023-04-24 20:40:15,972] {taskinstance.py:1397} INFO - Executing <Task(PrepareScopusData): prepare_scopus_data> on 2023-04-24 20:39:52.033408+00:00
[2023-04-24 20:40:15,980] {standard_task_runner.py:52} INFO - Started process 12753 to run task
[2023-04-24 20:40:15,987] {standard_task_runner.py:79} INFO - Running: ['***', 'tasks', 'run', 'vic_investigacion_ETL', 'prepare_scopus_data', 'manual__2023-04-24T20:39:52.033408+00:00', '--job-id', '455', '--raw', '--subdir', 'DAGS_FOLDER/vic_investigacion_dag.py', '--cfg-path', '/tmp/tmpsa4z73sp', '--error-file', '/tmp/tmpssljbp3u']
[2023-04-24 20:40:15,990] {standard_task_runner.py:80} INFO - Job 455: Subtask prepare_scopus_data
[2023-04-24 20:40:16,079] {task_command.py:371} INFO - Running <TaskInstance: vic_investigacion_ETL.prepare_scopus_data manual__2023-04-24T20:39:52.033408+00:00 [running]> on host b136a0a45498
[2023-04-24 20:40:16,302] {taskinstance.py:1591} INFO - Exporting the following env vars:
AIRFLOW_CTX_DAG_OWNER=***
AIRFLOW_CTX_DAG_ID=vic_investigacion_ETL
AIRFLOW_CTX_TASK_ID=prepare_scopus_data
AIRFLOW_CTX_EXECUTION_DATE=2023-04-24T20:39:52.033408+00:00
AIRFLOW_CTX_TRY_NUMBER=1
AIRFLOW_CTX_DAG_RUN_ID=manual__2023-04-24T20:39:52.033408+00:00
[2023-04-24 20:40:16,303] {logging_mixin.py:115} INFO - Preparing Scopus Data
[2023-04-24 20:40:16,330] {taskinstance.py:1909} ERROR - Task failed with exception
Traceback (most recent call last):
  File "/opt/airflow/dags/prepare_scopus_data_operator.py", line 21, in execute
    self.clean_authors_core_data()
  File "/opt/airflow/dags/prepare_scopus_data_operator.py", line 74, in clean_authors_core_data
    ],inplace=True)
  File "/home/airflow/.local/lib/python3.7/site-packages/pandas/util/_decorators.py", line 311, in wrapper
    return func(*args, **kwargs)
  File "/home/airflow/.local/lib/python3.7/site-packages/pandas/core/frame.py", line 4913, in drop
    errors=errors,
  File "/home/airflow/.local/lib/python3.7/site-packages/pandas/core/generic.py", line 4150, in drop
    obj = obj._drop_axis(labels, axis, level=level, errors=errors)
  File "/home/airflow/.local/lib/python3.7/site-packages/pandas/core/generic.py", line 4185, in _drop_axis
    new_axis = axis.drop(labels, errors=errors)
  File "/home/airflow/.local/lib/python3.7/site-packages/pandas/core/indexes/base.py", line 6017, in drop
    raise KeyError(f"{labels[mask]} not found in axis")
KeyError: "['affiliation_current.affiliation.ip_doc.afnameid'\n 'affiliation_current.affiliation.ip_doc.manual_curation.@curated'\n 'affiliation_current.affiliation.ip_doc.manual_curation.curation_type'\n 'affiliation_current.affiliation.ip_doc.manual_curation.curation_source'] not found in axis"
[2023-04-24 20:40:16,354] {taskinstance.py:1420} INFO - Marking task as FAILED. dag_id=vic_investigacion_ETL, task_id=prepare_scopus_data, execution_date=20230424T203952, start_date=20230424T204015, end_date=20230424T204016
[2023-04-24 20:40:16,362] {standard_task_runner.py:97} ERROR - Failed to execute job 455 for task prepare_scopus_data ("['affiliation_current.affiliation.ip_doc.afnameid'\n 'affiliation_current.affiliation.ip_doc.manual_curation.@curated'\n 'affiliation_current.affiliation.ip_doc.manual_curation.curation_type'\n 'affiliation_current.affiliation.ip_doc.manual_curation.curation_source'] not found in axis"; 12753)
[2023-04-24 20:40:16,414] {local_task_job.py:156} INFO - Task exited with return code 1
