[2023-08-02 22:30:45,513] {taskinstance.py:1179} INFO - Dependencies all met for <TaskInstance: vic_investigacion_ETL.proyectos manual__2023-08-02T22:30:41.645101+00:00 [queued]>
[2023-08-02 22:30:45,524] {taskinstance.py:1179} INFO - Dependencies all met for <TaskInstance: vic_investigacion_ETL.proyectos manual__2023-08-02T22:30:41.645101+00:00 [queued]>
[2023-08-02 22:30:45,525] {taskinstance.py:1376} INFO - 
--------------------------------------------------------------------------------
[2023-08-02 22:30:45,525] {taskinstance.py:1377} INFO - Starting attempt 1 of 1
[2023-08-02 22:30:45,526] {taskinstance.py:1378} INFO - 
--------------------------------------------------------------------------------
[2023-08-02 22:30:45,538] {taskinstance.py:1397} INFO - Executing <Task(PrepareProyectos): proyectos> on 2023-08-02 22:30:41.645101+00:00
[2023-08-02 22:30:45,549] {standard_task_runner.py:52} INFO - Started process 598 to run task
[2023-08-02 22:30:45,558] {standard_task_runner.py:79} INFO - Running: ['***', 'tasks', 'run', 'vic_investigacion_ETL', 'proyectos', 'manual__2023-08-02T22:30:41.645101+00:00', '--job-id', '201', '--raw', '--subdir', 'DAGS_FOLDER/vic_investigacion_dag.py', '--cfg-path', '/tmp/tmpxpuxc154', '--error-file', '/tmp/tmpr2jdbads']
[2023-08-02 22:30:45,561] {standard_task_runner.py:80} INFO - Job 201: Subtask proyectos
[2023-08-02 22:30:45,762] {task_command.py:371} INFO - Running <TaskInstance: vic_investigacion_ETL.proyectos manual__2023-08-02T22:30:41.645101+00:00 [running]> on host 6c8a51d4a614
[2023-08-02 22:30:45,903] {taskinstance.py:1591} INFO - Exporting the following env vars:
AIRFLOW_CTX_DAG_OWNER=***
AIRFLOW_CTX_DAG_ID=vic_investigacion_ETL
AIRFLOW_CTX_TASK_ID=proyectos
AIRFLOW_CTX_EXECUTION_DATE=2023-08-02T22:30:41.645101+00:00
AIRFLOW_CTX_TRY_NUMBER=1
AIRFLOW_CTX_DAG_RUN_ID=manual__2023-08-02T22:30:41.645101+00:00
[2023-08-02 22:30:45,907] {logging_mixin.py:115} INFO - Reading Journals
[2023-08-02 22:30:54,896] {taskinstance.py:1909} ERROR - Task failed with exception
Traceback (most recent call last):
  File "/opt/airflow/dags/prepare_proyectos_operator.py", line 22, in execute
    self.cleanData()
  File "/opt/airflow/dags/prepare_proyectos_operator.py", line 26, in cleanData
    self.cleanProyectos()
  File "/opt/airflow/dags/prepare_proyectos_operator.py", line 40, in cleanProyectos
    proyectos.to_csv(f"{self.dag_path}/data/to_upload/rewrite/proyectos.csv",index=False)
  File "/home/airflow/.local/lib/python3.7/site-packages/pandas/core/generic.py", line 3482, in to_csv
    storage_options=storage_options,
  File "/home/airflow/.local/lib/python3.7/site-packages/pandas/io/formats/format.py", line 1105, in to_csv
    csv_formatter.save()
  File "/home/airflow/.local/lib/python3.7/site-packages/pandas/io/formats/csvs.py", line 243, in save
    storage_options=self.storage_options,
  File "/home/airflow/.local/lib/python3.7/site-packages/pandas/io/common.py", line 707, in get_handle
    newline="",
FileNotFoundError: [Errno 2] No such file or directory: '/opt/airflow/data/to_upload/rewrite/proyectos.csv'
[2023-08-02 22:30:54,929] {taskinstance.py:1420} INFO - Marking task as FAILED. dag_id=vic_investigacion_ETL, task_id=proyectos, execution_date=20230802T223041, start_date=20230802T223045, end_date=20230802T223054
[2023-08-02 22:30:54,940] {standard_task_runner.py:97} ERROR - Failed to execute job 201 for task proyectos ([Errno 2] No such file or directory: '/opt/airflow/data/to_upload/rewrite/proyectos.csv'; 598)
[2023-08-02 22:30:55,058] {local_task_job.py:156} INFO - Task exited with return code 1
