[2023-08-02 22:30:45,482] {taskinstance.py:1179} INFO - Dependencies all met for <TaskInstance: vic_investigacion_ETL.revistas manual__2023-08-02T22:30:41.645101+00:00 [queued]>
[2023-08-02 22:30:45,491] {taskinstance.py:1179} INFO - Dependencies all met for <TaskInstance: vic_investigacion_ETL.revistas manual__2023-08-02T22:30:41.645101+00:00 [queued]>
[2023-08-02 22:30:45,492] {taskinstance.py:1376} INFO - 
--------------------------------------------------------------------------------
[2023-08-02 22:30:45,492] {taskinstance.py:1377} INFO - Starting attempt 1 of 1
[2023-08-02 22:30:45,493] {taskinstance.py:1378} INFO - 
--------------------------------------------------------------------------------
[2023-08-02 22:30:45,504] {taskinstance.py:1397} INFO - Executing <Task(PrepareRevistas): revistas> on 2023-08-02 22:30:41.645101+00:00
[2023-08-02 22:30:45,534] {standard_task_runner.py:52} INFO - Started process 597 to run task
[2023-08-02 22:30:45,542] {standard_task_runner.py:79} INFO - Running: ['***', 'tasks', 'run', 'vic_investigacion_ETL', 'revistas', 'manual__2023-08-02T22:30:41.645101+00:00', '--job-id', '203', '--raw', '--subdir', 'DAGS_FOLDER/vic_investigacion_dag.py', '--cfg-path', '/tmp/tmp2wjrsmkx', '--error-file', '/tmp/tmpqyycfywh']
[2023-08-02 22:30:45,546] {standard_task_runner.py:80} INFO - Job 203: Subtask revistas
[2023-08-02 22:30:45,745] {task_command.py:371} INFO - Running <TaskInstance: vic_investigacion_ETL.revistas manual__2023-08-02T22:30:41.645101+00:00 [running]> on host 6c8a51d4a614
[2023-08-02 22:30:45,916] {taskinstance.py:1591} INFO - Exporting the following env vars:
AIRFLOW_CTX_DAG_OWNER=***
AIRFLOW_CTX_DAG_ID=vic_investigacion_ETL
AIRFLOW_CTX_TASK_ID=revistas
AIRFLOW_CTX_EXECUTION_DATE=2023-08-02T22:30:41.645101+00:00
AIRFLOW_CTX_TRY_NUMBER=1
AIRFLOW_CTX_DAG_RUN_ID=manual__2023-08-02T22:30:41.645101+00:00
[2023-08-02 22:30:45,923] {logging_mixin.py:115} INFO - Reading Revistas
[2023-08-02 22:31:12,649] {taskinstance.py:1909} ERROR - Task failed with exception
Traceback (most recent call last):
  File "/opt/airflow/dags/prepare_revistas_operator.py", line 20, in execute
    self.cleanData()
  File "/opt/airflow/dags/prepare_revistas_operator.py", line 24, in cleanData
    self.cleanRevistas()
  File "/opt/airflow/dags/prepare_revistas_operator.py", line 34, in cleanRevistas
    revistas.to_csv(f"{self.dag_path}/data/to_upload/append/revistas.csv",index=False)
  File "/home/airflow/.local/lib/python3.7/site-packages/pandas/core/generic.py", line 3482, in to_csv
    storage_options=storage_options,
  File "/home/airflow/.local/lib/python3.7/site-packages/pandas/io/formats/format.py", line 1105, in to_csv
    csv_formatter.save()
  File "/home/airflow/.local/lib/python3.7/site-packages/pandas/io/formats/csvs.py", line 243, in save
    storage_options=self.storage_options,
  File "/home/airflow/.local/lib/python3.7/site-packages/pandas/io/common.py", line 707, in get_handle
    newline="",
FileNotFoundError: [Errno 2] No such file or directory: '/opt/airflow/data/to_upload/append/revistas.csv'
[2023-08-02 22:31:12,752] {taskinstance.py:1420} INFO - Marking task as FAILED. dag_id=vic_investigacion_ETL, task_id=revistas, execution_date=20230802T223041, start_date=20230802T223045, end_date=20230802T223112
[2023-08-02 22:31:12,762] {standard_task_runner.py:97} ERROR - Failed to execute job 203 for task revistas ([Errno 2] No such file or directory: '/opt/airflow/data/to_upload/append/revistas.csv'; 597)
[2023-08-02 22:31:12,845] {local_task_job.py:156} INFO - Task exited with return code 1
