[2023-06-26 12:23:30,388] {taskinstance.py:1179} INFO - Dependencies all met for <TaskInstance: vic_investigacion_ETL.upload_data_big_query manual__2023-06-26T12:22:58.538209+00:00 [queued]>
[2023-06-26 12:23:30,398] {taskinstance.py:1179} INFO - Dependencies all met for <TaskInstance: vic_investigacion_ETL.upload_data_big_query manual__2023-06-26T12:22:58.538209+00:00 [queued]>
[2023-06-26 12:23:30,399] {taskinstance.py:1376} INFO - 
--------------------------------------------------------------------------------
[2023-06-26 12:23:30,400] {taskinstance.py:1377} INFO - Starting attempt 1 of 1
[2023-06-26 12:23:30,400] {taskinstance.py:1378} INFO - 
--------------------------------------------------------------------------------
[2023-06-26 12:23:30,411] {taskinstance.py:1397} INFO - Executing <Task(ExportData): upload_data_big_query> on 2023-06-26 12:22:58.538209+00:00
[2023-06-26 12:23:30,417] {standard_task_runner.py:52} INFO - Started process 2220 to run task
[2023-06-26 12:23:30,422] {standard_task_runner.py:79} INFO - Running: ['***', 'tasks', 'run', 'vic_investigacion_ETL', 'upload_data_big_query', 'manual__2023-06-26T12:22:58.538209+00:00', '--job-id', '7', '--raw', '--subdir', 'DAGS_FOLDER/vic_investigacion_dag.py', '--cfg-path', '/tmp/tmppqjbn0xx', '--error-file', '/tmp/tmpzondqlfi']
[2023-06-26 12:23:30,424] {standard_task_runner.py:80} INFO - Job 7: Subtask upload_data_big_query
[2023-06-26 12:23:30,503] {task_command.py:371} INFO - Running <TaskInstance: vic_investigacion_ETL.upload_data_big_query manual__2023-06-26T12:22:58.538209+00:00 [running]> on host ce13f1e72365
[2023-06-26 12:23:30,561] {taskinstance.py:1591} INFO - Exporting the following env vars:
AIRFLOW_CTX_DAG_OWNER=***
AIRFLOW_CTX_DAG_ID=vic_investigacion_ETL
AIRFLOW_CTX_TASK_ID=upload_data_big_query
AIRFLOW_CTX_EXECUTION_DATE=2023-06-26T12:22:58.538209+00:00
AIRFLOW_CTX_TRY_NUMBER=1
AIRFLOW_CTX_DAG_RUN_ID=manual__2023-06-26T12:22:58.538209+00:00
[2023-06-26 12:23:30,564] {logging_mixin.py:115} INFO - Exporting Data
[2023-06-26 12:23:30,567] {logging_mixin.py:115} INFO - /opt/***/data/to_upload/respositorio_inst.xlsx
[2023-06-26 12:23:30,588] {taskinstance.py:1909} ERROR - Task failed with exception
Traceback (most recent call last):
  File "/opt/airflow/dags/export_data_operator.py", line 28, in execute
    self.export_data()
  File "/opt/airflow/dags/export_data_operator.py", line 55, in export_data
    df = pd.read_csv(file_path)
  File "/home/airflow/.local/lib/python3.7/site-packages/pandas/util/_decorators.py", line 311, in wrapper
    return func(*args, **kwargs)
  File "/home/airflow/.local/lib/python3.7/site-packages/pandas/io/parsers/readers.py", line 586, in read_csv
    return _read(filepath_or_buffer, kwds)
  File "/home/airflow/.local/lib/python3.7/site-packages/pandas/io/parsers/readers.py", line 482, in _read
    parser = TextFileReader(filepath_or_buffer, **kwds)
  File "/home/airflow/.local/lib/python3.7/site-packages/pandas/io/parsers/readers.py", line 811, in __init__
    self._engine = self._make_engine(self.engine)
  File "/home/airflow/.local/lib/python3.7/site-packages/pandas/io/parsers/readers.py", line 1040, in _make_engine
    return mapping[engine](self.f, **self.options)  # type: ignore[call-arg]
  File "/home/airflow/.local/lib/python3.7/site-packages/pandas/io/parsers/c_parser_wrapper.py", line 69, in __init__
    self._reader = parsers.TextReader(self.handles.handle, **kwds)
  File "pandas/_libs/parsers.pyx", line 542, in pandas._libs.parsers.TextReader.__cinit__
  File "pandas/_libs/parsers.pyx", line 642, in pandas._libs.parsers.TextReader._get_header
  File "pandas/_libs/parsers.pyx", line 843, in pandas._libs.parsers.TextReader._tokenize_rows
  File "pandas/_libs/parsers.pyx", line 1917, in pandas._libs.parsers.raise_parser_error
UnicodeDecodeError: 'utf-8' codec can't decode byte 0xe7 in position 10: invalid continuation byte
[2023-06-26 12:23:30,604] {taskinstance.py:1420} INFO - Marking task as FAILED. dag_id=vic_investigacion_ETL, task_id=upload_data_big_query, execution_date=20230626T122258, start_date=20230626T122330, end_date=20230626T122330
[2023-06-26 12:23:30,615] {standard_task_runner.py:97} ERROR - Failed to execute job 7 for task upload_data_big_query ('utf-8' codec can't decode byte 0xe7 in position 10: invalid continuation byte; 2220)
[2023-06-26 12:23:30,636] {local_task_job.py:156} INFO - Task exited with return code 1
[2023-06-26 12:23:30,671] {local_task_job.py:273} INFO - 0 downstream tasks scheduled from follow-on schedule check
