[2023-04-17 17:36:25,860] {taskinstance.py:1179} INFO - Dependencies all met for <TaskInstance: vic_investigacion_ETL.upload_data_big_query manual__2023-04-17T17:36:20.292137+00:00 [queued]>
[2023-04-17 17:36:25,866] {taskinstance.py:1179} INFO - Dependencies all met for <TaskInstance: vic_investigacion_ETL.upload_data_big_query manual__2023-04-17T17:36:20.292137+00:00 [queued]>
[2023-04-17 17:36:25,867] {taskinstance.py:1376} INFO - 
--------------------------------------------------------------------------------
[2023-04-17 17:36:25,867] {taskinstance.py:1377} INFO - Starting attempt 1 of 1
[2023-04-17 17:36:25,868] {taskinstance.py:1378} INFO - 
--------------------------------------------------------------------------------
[2023-04-17 17:36:25,875] {taskinstance.py:1397} INFO - Executing <Task(ExportingData): upload_data_big_query> on 2023-04-17 17:36:20.292137+00:00
[2023-04-17 17:36:25,880] {standard_task_runner.py:52} INFO - Started process 472 to run task
[2023-04-17 17:36:25,884] {standard_task_runner.py:79} INFO - Running: ['***', 'tasks', 'run', 'vic_investigacion_ETL', 'upload_data_big_query', 'manual__2023-04-17T17:36:20.292137+00:00', '--job-id', '211', '--raw', '--subdir', 'DAGS_FOLDER/vic_investigacion_dag.py', '--cfg-path', '/tmp/tmp4o5uamg8', '--error-file', '/tmp/tmp4qi6jsrj']
[2023-04-17 17:36:25,886] {standard_task_runner.py:80} INFO - Job 211: Subtask upload_data_big_query
[2023-04-17 17:36:25,939] {task_command.py:371} INFO - Running <TaskInstance: vic_investigacion_ETL.upload_data_big_query manual__2023-04-17T17:36:20.292137+00:00 [running]> on host 6071715564b2
[2023-04-17 17:36:25,997] {taskinstance.py:1591} INFO - Exporting the following env vars:
AIRFLOW_CTX_DAG_OWNER=***
AIRFLOW_CTX_DAG_ID=vic_investigacion_ETL
AIRFLOW_CTX_TASK_ID=upload_data_big_query
AIRFLOW_CTX_EXECUTION_DATE=2023-04-17T17:36:20.292137+00:00
AIRFLOW_CTX_TRY_NUMBER=1
AIRFLOW_CTX_DAG_RUN_ID=manual__2023-04-17T17:36:20.292137+00:00
[2023-04-17 17:36:25,998] {logging_mixin.py:115} INFO - Exporting Data
[2023-04-17 17:36:26,000] {logging_mixin.py:115} INFO - /opt/***/raw_data/clean_authors_core_data/afilliations_history.csv
[2023-04-17 17:36:28,080] {taskinstance.py:1909} ERROR - Task failed with exception
Traceback (most recent call last):
  File "/home/airflow/.local/lib/python3.7/site-packages/google/cloud/bigquery/client.py", line 2452, in load_table_from_file
    file_obj, job_resource, size, num_retries, timeout, project=project
  File "/home/airflow/.local/lib/python3.7/site-packages/google/cloud/bigquery/client.py", line 3022, in _do_multipart_upload
    self._http, data, metadata, _GENERIC_CONTENT_TYPE, timeout=timeout
  File "/home/airflow/.local/lib/python3.7/site-packages/google/resumable_media/requests/upload.py", line 154, in transmit
    retriable_request, self._get_status_code, self._retry_strategy
  File "/home/airflow/.local/lib/python3.7/site-packages/google/resumable_media/requests/_request_helpers.py", line 148, in wait_and_retry
    response = func()
  File "/home/airflow/.local/lib/python3.7/site-packages/google/resumable_media/requests/upload.py", line 149, in retriable_request
    self._process_response(result)
  File "/home/airflow/.local/lib/python3.7/site-packages/google/resumable_media/_upload.py", line 114, in _process_response
    _helpers.require_status_code(response, (http.client.OK,), self._get_status_code)
  File "/home/airflow/.local/lib/python3.7/site-packages/google/resumable_media/_helpers.py", line 110, in require_status_code
    *status_codes
google.resumable_media.common.InvalidResponse: ('Request failed with status code', 400, 'Expected one of', <HTTPStatus.OK: 200>)

During handling of the above exception, another exception occurred:

Traceback (most recent call last):
  File "/opt/airflow/dags/exporting_data_operator.py", line 28, in execute
    self.exporting_authors_core_data()
  File "/opt/airflow/dags/exporting_data_operator.py", line 59, in exporting_authors_core_data
    self.createTable(file_name,df)
  File "/opt/airflow/dags/exporting_data_operator.py", line 40, in createTable
    job= self.client.load_table_from_dataframe(df,full_table_id)
  File "/home/airflow/.local/lib/python3.7/site-packages/google/cloud/bigquery/client.py", line 2713, in load_table_from_dataframe
    timeout=timeout,
  File "/home/airflow/.local/lib/python3.7/site-packages/google/cloud/bigquery/client.py", line 2455, in load_table_from_file
    raise exceptions.from_http_response(exc.response)
google.api_core.exceptions.BadRequest: 400 POST https://bigquery.googleapis.com/upload/bigquery/v2/projects/viceinvestigacion/jobs?uploadType=multipart: Invalid field name "@affiliation-id". Fields must contain the allowed characters, and be at most 300 characters long. For allowed characters, please refer to https://cloud.google.com/bigquery/docs/schemas#column_names
[2023-04-17 17:36:28,124] {taskinstance.py:1420} INFO - Marking task as FAILED. dag_id=vic_investigacion_ETL, task_id=upload_data_big_query, execution_date=20230417T173620, start_date=20230417T173625, end_date=20230417T173628
[2023-04-17 17:36:28,144] {standard_task_runner.py:97} ERROR - Failed to execute job 211 for task upload_data_big_query (400 POST https://bigquery.googleapis.com/upload/bigquery/v2/projects/viceinvestigacion/jobs?uploadType=multipart: Invalid field name "@affiliation-id". Fields must contain the allowed characters, and be at most 300 characters long. For allowed characters, please refer to https://cloud.google.com/bigquery/docs/schemas#column_names; 472)
[2023-04-17 17:36:28,209] {local_task_job.py:156} INFO - Task exited with return code 1
[2023-04-17 17:36:28,244] {local_task_job.py:273} INFO - 0 downstream tasks scheduled from follow-on schedule check
