[2023-08-01 23:42:52,189] {taskinstance.py:1179} INFO - Dependencies all met for <TaskInstance: vic_investigacion_ETL.proyectos manual__2023-08-01T23:42:48.488920+00:00 [queued]>
[2023-08-01 23:42:52,211] {taskinstance.py:1179} INFO - Dependencies all met for <TaskInstance: vic_investigacion_ETL.proyectos manual__2023-08-01T23:42:48.488920+00:00 [queued]>
[2023-08-01 23:42:52,214] {taskinstance.py:1376} INFO - 
--------------------------------------------------------------------------------
[2023-08-01 23:42:52,217] {taskinstance.py:1377} INFO - Starting attempt 1 of 1
[2023-08-01 23:42:52,220] {taskinstance.py:1378} INFO - 
--------------------------------------------------------------------------------
[2023-08-01 23:42:52,265] {taskinstance.py:1397} INFO - Executing <Task(PrepareProyectos): proyectos> on 2023-08-01 23:42:48.488920+00:00
[2023-08-01 23:42:52,277] {standard_task_runner.py:52} INFO - Started process 2399 to run task
[2023-08-01 23:42:52,290] {standard_task_runner.py:79} INFO - Running: ['***', 'tasks', 'run', 'vic_investigacion_ETL', 'proyectos', 'manual__2023-08-01T23:42:48.488920+00:00', '--job-id', '186', '--raw', '--subdir', 'DAGS_FOLDER/vic_investigacion_dag.py', '--cfg-path', '/tmp/tmpt7ppd93y', '--error-file', '/tmp/tmpkpkonemc']
[2023-08-01 23:42:52,296] {standard_task_runner.py:80} INFO - Job 186: Subtask proyectos
[2023-08-01 23:42:52,585] {task_command.py:371} INFO - Running <TaskInstance: vic_investigacion_ETL.proyectos manual__2023-08-01T23:42:48.488920+00:00 [running]> on host 6c8a51d4a614
[2023-08-01 23:42:52,853] {taskinstance.py:1591} INFO - Exporting the following env vars:
AIRFLOW_CTX_DAG_OWNER=***
AIRFLOW_CTX_DAG_ID=vic_investigacion_ETL
AIRFLOW_CTX_TASK_ID=proyectos
AIRFLOW_CTX_EXECUTION_DATE=2023-08-01T23:42:48.488920+00:00
AIRFLOW_CTX_TRY_NUMBER=1
AIRFLOW_CTX_DAG_RUN_ID=manual__2023-08-01T23:42:48.488920+00:00
[2023-08-01 23:42:52,865] {logging_mixin.py:115} INFO - Reading Journals
[2023-08-01 23:43:04,724] {taskinstance.py:1909} ERROR - Task failed with exception
Traceback (most recent call last):
  File "/opt/airflow/dags/prepare_proyectos_operator.py", line 22, in execute
    self.cleanData()
  File "/opt/airflow/dags/prepare_proyectos_operator.py", line 26, in cleanData
    self.cleanProyectos()
  File "/opt/airflow/dags/prepare_proyectos_operator.py", line 39, in cleanProyectos
    proyectos['FECHA_DE_NEGOCIACION'] = proyectos['FECHA_DE_NEGOCIACION'].apply(lambda x: self._convert_to_datetime(x))
  File "/home/airflow/.local/lib/python3.7/site-packages/pandas/core/series.py", line 4357, in apply
    return SeriesApply(self, func, convert_dtype, args, kwargs).apply()
  File "/home/airflow/.local/lib/python3.7/site-packages/pandas/core/apply.py", line 1043, in apply
    return self.apply_standard()
  File "/home/airflow/.local/lib/python3.7/site-packages/pandas/core/apply.py", line 1101, in apply_standard
    convert=self.convert_dtype,
  File "pandas/_libs/lib.pyx", line 2859, in pandas._libs.lib.map_infer
  File "/opt/airflow/dags/prepare_proyectos_operator.py", line 39, in <lambda>
    proyectos['FECHA_DE_NEGOCIACION'] = proyectos['FECHA_DE_NEGOCIACION'].apply(lambda x: self._convert_to_datetime(x))
TypeError: _convert_to_datetime() takes 1 positional argument but 2 were given
[2023-08-01 23:43:04,780] {taskinstance.py:1420} INFO - Marking task as FAILED. dag_id=vic_investigacion_ETL, task_id=proyectos, execution_date=20230801T234248, start_date=20230801T234252, end_date=20230801T234304
[2023-08-01 23:43:04,809] {standard_task_runner.py:97} ERROR - Failed to execute job 186 for task proyectos (_convert_to_datetime() takes 1 positional argument but 2 were given; 2399)
[2023-08-01 23:43:04,971] {local_task_job.py:156} INFO - Task exited with return code 1
