[2023-04-24 17:25:13,878] {taskinstance.py:1179} INFO - Dependencies all met for <TaskInstance: vic_investigacion_ETL.join_all_data manual__2023-04-24T17:25:07.968983+00:00 [queued]>
[2023-04-24 17:25:13,885] {taskinstance.py:1179} INFO - Dependencies all met for <TaskInstance: vic_investigacion_ETL.join_all_data manual__2023-04-24T17:25:07.968983+00:00 [queued]>
[2023-04-24 17:25:13,886] {taskinstance.py:1376} INFO - 
--------------------------------------------------------------------------------
[2023-04-24 17:25:13,886] {taskinstance.py:1377} INFO - Starting attempt 1 of 1
[2023-04-24 17:25:13,887] {taskinstance.py:1378} INFO - 
--------------------------------------------------------------------------------
[2023-04-24 17:25:13,895] {taskinstance.py:1397} INFO - Executing <Task(JoinAllData): join_all_data> on 2023-04-24 17:25:07.968983+00:00
[2023-04-24 17:25:13,903] {standard_task_runner.py:52} INFO - Started process 6065 to run task
[2023-04-24 17:25:13,907] {standard_task_runner.py:79} INFO - Running: ['***', 'tasks', 'run', 'vic_investigacion_ETL', 'join_all_data', 'manual__2023-04-24T17:25:07.968983+00:00', '--job-id', '391', '--raw', '--subdir', 'DAGS_FOLDER/vic_investigacion_dag.py', '--cfg-path', '/tmp/tmpgjmkl_c0', '--error-file', '/tmp/tmps4na1qfw']
[2023-04-24 17:25:13,909] {standard_task_runner.py:80} INFO - Job 391: Subtask join_all_data
[2023-04-24 17:25:13,986] {task_command.py:371} INFO - Running <TaskInstance: vic_investigacion_ETL.join_all_data manual__2023-04-24T17:25:07.968983+00:00 [running]> on host b136a0a45498
[2023-04-24 17:25:14,059] {taskinstance.py:1591} INFO - Exporting the following env vars:
AIRFLOW_CTX_DAG_OWNER=***
AIRFLOW_CTX_DAG_ID=vic_investigacion_ETL
AIRFLOW_CTX_TASK_ID=join_all_data
AIRFLOW_CTX_EXECUTION_DATE=2023-04-24T17:25:07.968983+00:00
AIRFLOW_CTX_TRY_NUMBER=1
AIRFLOW_CTX_DAG_RUN_ID=manual__2023-04-24T17:25:07.968983+00:00
[2023-04-24 17:25:14,060] {logging_mixin.py:115} INFO - Joining all data
[2023-04-24 17:25:14,218] {taskinstance.py:1909} ERROR - Task failed with exception
Traceback (most recent call last):
  File "/opt/airflow/dags/join_all_data_operator.py", line 20, in execute
    self.joinScopusData()
  File "/opt/airflow/dags/join_all_data_operator.py", line 31, in joinScopusData
    join_df = pd.merge(coredata,affiliation_current, how="left", left_on='Scopus_id', right_on='Scopus_id')
  File "/home/airflow/.local/lib/python3.7/site-packages/pandas/core/reshape/merge.py", line 119, in merge
    validate=validate,
  File "/home/airflow/.local/lib/python3.7/site-packages/pandas/core/reshape/merge.py", line 699, in __init__
    ) = self._get_merge_keys()
  File "/home/airflow/.local/lib/python3.7/site-packages/pandas/core/reshape/merge.py", line 1096, in _get_merge_keys
    right_keys.append(right._get_label_or_level_values(rk))
  File "/home/airflow/.local/lib/python3.7/site-packages/pandas/core/generic.py", line 1779, in _get_label_or_level_values
    raise KeyError(key)
KeyError: 'Scopus_id'
[2023-04-24 17:25:14,251] {taskinstance.py:1420} INFO - Marking task as FAILED. dag_id=vic_investigacion_ETL, task_id=join_all_data, execution_date=20230424T172507, start_date=20230424T172513, end_date=20230424T172514
[2023-04-24 17:25:14,260] {standard_task_runner.py:97} ERROR - Failed to execute job 391 for task join_all_data ('Scopus_id'; 6065)
[2023-04-24 17:25:14,289] {local_task_job.py:156} INFO - Task exited with return code 1
