[2023-08-02 22:32:02,983] {taskinstance.py:1179} INFO - Dependencies all met for <TaskInstance: vic_investigacion_ETL.semilleros manual__2023-08-02T22:32:00.479946+00:00 [queued]>
[2023-08-02 22:32:02,998] {taskinstance.py:1179} INFO - Dependencies all met for <TaskInstance: vic_investigacion_ETL.semilleros manual__2023-08-02T22:32:00.479946+00:00 [queued]>
[2023-08-02 22:32:03,000] {taskinstance.py:1376} INFO - 
--------------------------------------------------------------------------------
[2023-08-02 22:32:03,001] {taskinstance.py:1377} INFO - Starting attempt 1 of 1
[2023-08-02 22:32:03,004] {taskinstance.py:1378} INFO - 
--------------------------------------------------------------------------------
[2023-08-02 22:32:03,021] {taskinstance.py:1397} INFO - Executing <Task(PrepareSemilleros): semilleros> on 2023-08-02 22:32:00.479946+00:00
[2023-08-02 22:32:03,036] {standard_task_runner.py:52} INFO - Started process 681 to run task
[2023-08-02 22:32:03,050] {standard_task_runner.py:79} INFO - Running: ['***', 'tasks', 'run', 'vic_investigacion_ETL', 'semilleros', 'manual__2023-08-02T22:32:00.479946+00:00', '--job-id', '211', '--raw', '--subdir', 'DAGS_FOLDER/vic_investigacion_dag.py', '--cfg-path', '/tmp/tmpyy_z3tik', '--error-file', '/tmp/tmp11gmttsk']
[2023-08-02 22:32:03,055] {standard_task_runner.py:80} INFO - Job 211: Subtask semilleros
[2023-08-02 22:32:03,265] {task_command.py:371} INFO - Running <TaskInstance: vic_investigacion_ETL.semilleros manual__2023-08-02T22:32:00.479946+00:00 [running]> on host 6c8a51d4a614
[2023-08-02 22:32:03,414] {taskinstance.py:1591} INFO - Exporting the following env vars:
AIRFLOW_CTX_DAG_OWNER=***
AIRFLOW_CTX_DAG_ID=vic_investigacion_ETL
AIRFLOW_CTX_TASK_ID=semilleros
AIRFLOW_CTX_EXECUTION_DATE=2023-08-02T22:32:00.479946+00:00
AIRFLOW_CTX_TRY_NUMBER=1
AIRFLOW_CTX_DAG_RUN_ID=manual__2023-08-02T22:32:00.479946+00:00
[2023-08-02 22:32:03,424] {logging_mixin.py:115} INFO - Reading Semilleros
[2023-08-02 22:32:03,433] {taskinstance.py:1909} ERROR - Task failed with exception
Traceback (most recent call last):
  File "/opt/airflow/dags/prepare_semilleros_operator.py", line 22, in execute
    self.cleanData()
  File "/opt/airflow/dags/prepare_semilleros_operator.py", line 26, in cleanData
    self.cleanSemilleros()
  File "/opt/airflow/dags/prepare_semilleros_operator.py", line 30, in cleanSemilleros
    semilleros = pd.read_excel(f"{self.dag_path}/data/semilleros/rewrite/semilleros_template.xlsx")
  File "/home/airflow/.local/lib/python3.7/site-packages/pandas/util/_decorators.py", line 311, in wrapper
    return func(*args, **kwargs)
  File "/home/airflow/.local/lib/python3.7/site-packages/pandas/io/excel/_base.py", line 364, in read_excel
    io = ExcelFile(io, storage_options=storage_options, engine=engine)
  File "/home/airflow/.local/lib/python3.7/site-packages/pandas/io/excel/_base.py", line 1192, in __init__
    content_or_path=path_or_buffer, storage_options=storage_options
  File "/home/airflow/.local/lib/python3.7/site-packages/pandas/io/excel/_base.py", line 1071, in inspect_excel_format
    content_or_path, "rb", storage_options=storage_options, is_text=False
  File "/home/airflow/.local/lib/python3.7/site-packages/pandas/io/common.py", line 711, in get_handle
    handle = open(handle, ioargs.mode)
FileNotFoundError: [Errno 2] No such file or directory: '/opt/airflow/data/semilleros/rewrite/semilleros_template.xlsx'
[2023-08-02 22:32:03,480] {taskinstance.py:1420} INFO - Marking task as FAILED. dag_id=vic_investigacion_ETL, task_id=semilleros, execution_date=20230802T223200, start_date=20230802T223202, end_date=20230802T223203
[2023-08-02 22:32:03,492] {standard_task_runner.py:97} ERROR - Failed to execute job 211 for task semilleros ([Errno 2] No such file or directory: '/opt/airflow/data/semilleros/rewrite/semilleros_template.xlsx'; 681)
[2023-08-02 22:32:03,546] {local_task_job.py:156} INFO - Task exited with return code 1
